nohup: ignoring input
[2024-07-18 16:53:06 +0000] [10328] [INFO] Starting gunicorn 21.2.0
[2024-07-18 16:53:06 +0000] [10328] [INFO] Listening at: http://0.0.0.0:8000 (10328)
[2024-07-18 16:53:06 +0000] [10328] [INFO] Using worker: sync
[2024-07-18 16:53:06 +0000] [10331] [INFO] Booting worker with pid: 10331
Internal Server Error: /SOS/listar/meus/chamados/todos/
Traceback (most recent call last):
  File "/home/administrador/venv/lib/python3.6/site-packages/django/contrib/sessions/backends/base.py", line 199, in _get_session
    return self._session_cache
AttributeError: 'SessionStore' object has no attribute '_session_cache'

During handling of the above exception, another exception occurred:

Traceback (most recent call last):
  File "/home/administrador/venv/lib/python3.6/site-packages/django/db/backends/base/base.py", line 220, in ensure_connection
    self.connect()
  File "/home/administrador/venv/lib/python3.6/site-packages/django/utils/asyncio.py", line 26, in inner
    return func(*args, **kwargs)
  File "/home/administrador/venv/lib/python3.6/site-packages/django/db/backends/base/base.py", line 197, in connect
    self.connection = self.get_new_connection(conn_params)
  File "/home/administrador/venv/lib/python3.6/site-packages/django/utils/asyncio.py", line 26, in inner
    return func(*args, **kwargs)
  File "/home/administrador/venv/lib/python3.6/site-packages/django/db/backends/sqlite3/base.py", line 199, in get_new_connection
    conn = Database.connect(**conn_params)
sqlite3.OperationalError: unable to open database file

The above exception was the direct cause of the following exception:

Traceback (most recent call last):
  File "/home/administrador/venv/lib/python3.6/site-packages/django/core/handlers/exception.py", line 34, in inner
    response = get_response(request)
  File "/home/administrador/venv/lib/python3.6/site-packages/django/utils/deprecation.py", line 93, in __call__
    response = self.process_request(request)
  File "/home/administrador/venv/lib/python3.6/site-packages/django_session_timeout/middleware.py", line 21, in process_request
    init_time = request.session.setdefault(SESSION_TIMEOUT_KEY, time.time())
  File "/home/administrador/venv/lib/python3.6/site-packages/django/contrib/sessions/backends/base.py", line 83, in setdefault
    if key in self._session:
  File "/home/administrador/venv/lib/python3.6/site-packages/django/contrib/sessions/backends/base.py", line 204, in _get_session
    self._session_cache = self.load()
  File "/home/administrador/venv/lib/python3.6/site-packages/django/contrib/sessions/backends/db.py", line 43, in load
    s = self._get_session_from_db()
  File "/home/administrador/venv/lib/python3.6/site-packages/django/contrib/sessions/backends/db.py", line 34, in _get_session_from_db
    expire_date__gt=timezone.now()
  File "/home/administrador/venv/lib/python3.6/site-packages/django/db/models/manager.py", line 82, in manager_method
    return getattr(self.get_queryset(), name)(*args, **kwargs)
  File "/home/administrador/venv/lib/python3.6/site-packages/django/db/models/query.py", line 411, in get
    num = len(clone)
  File "/home/administrador/venv/lib/python3.6/site-packages/django/db/models/query.py", line 258, in __len__
    self._fetch_all()
  File "/home/administrador/venv/lib/python3.6/site-packages/django/db/models/query.py", line 1261, in _fetch_all
    self._result_cache = list(self._iterable_class(self))
  File "/home/administrador/venv/lib/python3.6/site-packages/django/db/models/query.py", line 57, in __iter__
    results = compiler.execute_sql(chunked_fetch=self.chunked_fetch, chunk_size=self.chunk_size)
  File "/home/administrador/venv/lib/python3.6/site-packages/django/db/models/sql/compiler.py", line 1152, in execute_sql
    cursor = self.connection.cursor()
  File "/home/administrador/venv/lib/python3.6/site-packages/django/utils/asyncio.py", line 26, in inner
    return func(*args, **kwargs)
  File "/home/administrador/venv/lib/python3.6/site-packages/django/db/backends/base/base.py", line 260, in cursor
    return self._cursor()
  File "/home/administrador/venv/lib/python3.6/site-packages/django/db/backends/base/base.py", line 236, in _cursor
    self.ensure_connection()
  File "/home/administrador/venv/lib/python3.6/site-packages/django/utils/asyncio.py", line 26, in inner
    return func(*args, **kwargs)
  File "/home/administrador/venv/lib/python3.6/site-packages/django/db/backends/base/base.py", line 220, in ensure_connection
    self.connect()
  File "/home/administrador/venv/lib/python3.6/site-packages/django/db/utils.py", line 90, in __exit__
    raise dj_exc_value.with_traceback(traceback) from exc_value
  File "/home/administrador/venv/lib/python3.6/site-packages/django/db/backends/base/base.py", line 220, in ensure_connection
    self.connect()
  File "/home/administrador/venv/lib/python3.6/site-packages/django/utils/asyncio.py", line 26, in inner
    return func(*args, **kwargs)
  File "/home/administrador/venv/lib/python3.6/site-packages/django/db/backends/base/base.py", line 197, in connect
    self.connection = self.get_new_connection(conn_params)
  File "/home/administrador/venv/lib/python3.6/site-packages/django/utils/asyncio.py", line 26, in inner
    return func(*args, **kwargs)
  File "/home/administrador/venv/lib/python3.6/site-packages/django/db/backends/sqlite3/base.py", line 199, in get_new_connection
    conn = Database.connect(**conn_params)
django.db.utils.OperationalError: unable to open database file
Internal Server Error: /
Traceback (most recent call last):
  File "/home/administrador/venv/lib/python3.6/site-packages/django/contrib/sessions/backends/base.py", line 199, in _get_session
    return self._session_cache
AttributeError: 'SessionStore' object has no attribute '_session_cache'

During handling of the above exception, another exception occurred:

Traceback (most recent call last):
  File "/home/administrador/venv/lib/python3.6/site-packages/django/db/backends/base/base.py", line 220, in ensure_connection
    self.connect()
  File "/home/administrador/venv/lib/python3.6/site-packages/django/utils/asyncio.py", line 26, in inner
    return func(*args, **kwargs)
  File "/home/administrador/venv/lib/python3.6/site-packages/django/db/backends/base/base.py", line 197, in connect
    self.connection = self.get_new_connection(conn_params)
  File "/home/administrador/venv/lib/python3.6/site-packages/django/utils/asyncio.py", line 26, in inner
    return func(*args, **kwargs)
  File "/home/administrador/venv/lib/python3.6/site-packages/django/db/backends/sqlite3/base.py", line 199, in get_new_connection
    conn = Database.connect(**conn_params)
sqlite3.OperationalError: unable to open database file

The above exception was the direct cause of the following exception:

Traceback (most recent call last):
  File "/home/administrador/venv/lib/python3.6/site-packages/django/core/handlers/exception.py", line 34, in inner
    response = get_response(request)
  File "/home/administrador/venv/lib/python3.6/site-packages/django/utils/deprecation.py", line 93, in __call__
    response = self.process_request(request)
  File "/home/administrador/venv/lib/python3.6/site-packages/django_session_timeout/middleware.py", line 21, in process_request
    init_time = request.session.setdefault(SESSION_TIMEOUT_KEY, time.time())
  File "/home/administrador/venv/lib/python3.6/site-packages/django/contrib/sessions/backends/base.py", line 83, in setdefault
    if key in self._session:
  File "/home/administrador/venv/lib/python3.6/site-packages/django/contrib/sessions/backends/base.py", line 204, in _get_session
    self._session_cache = self.load()
  File "/home/administrador/venv/lib/python3.6/site-packages/django/contrib/sessions/backends/db.py", line 43, in load
    s = self._get_session_from_db()
  File "/home/administrador/venv/lib/python3.6/site-packages/django/contrib/sessions/backends/db.py", line 34, in _get_session_from_db
    expire_date__gt=timezone.now()
  File "/home/administrador/venv/lib/python3.6/site-packages/django/db/models/manager.py", line 82, in manager_method
    return getattr(self.get_queryset(), name)(*args, **kwargs)
  File "/home/administrador/venv/lib/python3.6/site-packages/django/db/models/query.py", line 411, in get
    num = len(clone)
  File "/home/administrador/venv/lib/python3.6/site-packages/django/db/models/query.py", line 258, in __len__
    self._fetch_all()
  File "/home/administrador/venv/lib/python3.6/site-packages/django/db/models/query.py", line 1261, in _fetch_all
    self._result_cache = list(self._iterable_class(self))
  File "/home/administrador/venv/lib/python3.6/site-packages/django/db/models/query.py", line 57, in __iter__
    results = compiler.execute_sql(chunked_fetch=self.chunked_fetch, chunk_size=self.chunk_size)
  File "/home/administrador/venv/lib/python3.6/site-packages/django/db/models/sql/compiler.py", line 1152, in execute_sql
    cursor = self.connection.cursor()
  File "/home/administrador/venv/lib/python3.6/site-packages/django/utils/asyncio.py", line 26, in inner
    return func(*args, **kwargs)
  File "/home/administrador/venv/lib/python3.6/site-packages/django/db/backends/base/base.py", line 260, in cursor
    return self._cursor()
  File "/home/administrador/venv/lib/python3.6/site-packages/django/db/backends/base/base.py", line 236, in _cursor
    self.ensure_connection()
  File "/home/administrador/venv/lib/python3.6/site-packages/django/utils/asyncio.py", line 26, in inner
    return func(*args, **kwargs)
  File "/home/administrador/venv/lib/python3.6/site-packages/django/db/backends/base/base.py", line 220, in ensure_connection
    self.connect()
  File "/home/administrador/venv/lib/python3.6/site-packages/django/db/utils.py", line 90, in __exit__
    raise dj_exc_value.with_traceback(traceback) from exc_value
  File "/home/administrador/venv/lib/python3.6/site-packages/django/db/backends/base/base.py", line 220, in ensure_connection
    self.connect()
  File "/home/administrador/venv/lib/python3.6/site-packages/django/utils/asyncio.py", line 26, in inner
    return func(*args, **kwargs)
  File "/home/administrador/venv/lib/python3.6/site-packages/django/db/backends/base/base.py", line 197, in connect
    self.connection = self.get_new_connection(conn_params)
  File "/home/administrador/venv/lib/python3.6/site-packages/django/utils/asyncio.py", line 26, in inner
    return func(*args, **kwargs)
  File "/home/administrador/venv/lib/python3.6/site-packages/django/db/backends/sqlite3/base.py", line 199, in get_new_connection
    conn = Database.connect(**conn_params)
django.db.utils.OperationalError: unable to open database file
[2024-07-18 16:54:38 +0000] [10328] [INFO] Handling signal: term
[2024-07-18 13:54:38 -0300] [10331] [INFO] Worker exiting (pid: 10331)
[2024-07-18 16:54:38 +0000] [10328] [ERROR] Worker (pid:10331) was sent SIGTERM!
[2024-07-18 16:54:38 +0000] [10328] [INFO] Shutting down: Master
